
### Test Results - 2025-04-20 00:34

#### Summary

| Metric | Value |
|--------|-------|
| Status | **FAILED** |
| Tests Run | 2 |
| Failures | 0 |
| Errors | 2 |
| Time | 0.00 seconds |

## Results by Test File

| Test File | Status | Pass/Total |
|-----------|--------|------------|
| unittest | ‚ùå FAILED | 0/2 |

## Failures and Errors

### Errors

#### unittest.loader._FailedTest.test_backup_manager_unittest
```
ImportError: Failed to import test module: test_backup_manager_unittest
Traceback (most recent call last):
  File "/usr/lib/python3.12/unittest/loader.py", line 396, in _find_test_path
    module = self._get_module_from_name(name)
             ^^^^^^^^^^^^^^^^^^^^^^^^^^^^^^^^
  File "/usr/lib/python3.12/unittest/loader.py", line 339, in _get_module_from_name
    __import__(name)
  File "/home/d0021/kool/mach3-retrofit-final-project/ToolManagement/Scripts/Tests/UnitTests/test_backup_manager_unittest.py", line 24, in <module>
    from backup_manager import BackupManager, BackupRotation
ModuleNotFoundError: No module named 'backup_manager'


```

#### unittest.loader._FailedTest.test_file_lock
```
ImportError: Failed to import test module: test_file_lock
Traceback (most recent call last):
  File "/usr/lib/python3.12/unittest/loader.py", line 396, in _find_test_path
    module = self._get_module_from_name(name)
             ^^^^^^^^^^^^^^^^^^^^^^^^^^^^^^^^
  File "/usr/lib/python3.12/unittest/loader.py", line 339, in _get_module_from_name
    __import__(name)
  File "/home/d0021/kool/mach3-retrofit-final-project/ToolManagement/Scripts/Tests/UnitTests/test_file_lock.py", line 16, in <module>
    from Backups.file_lock import FileLock
ModuleNotFoundError: No module named 'Backups'


```

